2024-09-25 13:14:32 - MyLogger - DEBUG - gRPC Server started on port 50051
2024-09-25 13:14:38 - urllib3.connectionpool - DEBUG - Starting new HTTPS connection (1): de.yuntech.poc.com:3443
2024-09-25 13:14:38 - urllib3.connectionpool - DEBUG - https://de.yuntech.poc.com:3443 "POST /agentfido/login/begin HTTP/1.1" 200 559
2024-09-25 13:14:48 - urllib3.connectionpool - DEBUG - Starting new HTTPS connection (1): de.yuntech.poc.com:3443
2024-09-25 13:14:48 - urllib3.connectionpool - DEBUG - https://de.yuntech.poc.com:3443 "POST /agentfido/login/complete HTTP/1.1" 404 750
2024-09-25 13:14:48 - grpc._server - ERROR - Exception calling application: cannot access local variable 'message' where it is not associated with a value
Traceback (most recent call last):
  File "/home/yunpep/non_web_protocal_zta/PEP/server/index/myvenv/lib/python3.12/site-packages/grpc/_server.py", line 609, in _call_behavior
    response_or_iterator = behavior(argument, context)
                           ^^^^^^^^^^^^^^^^^^^^^^^^^^^
  File "/home/yunpep/non_web_protocal_zta/PEP/server/index/grpc_server.py", line 154, in LoginComplete
    return credentials_pb2.Message(msg=message['data'])
                                       ^^^^^^^
UnboundLocalError: cannot access local variable 'message' where it is not associated with a value
2024-09-25 13:16:12 - urllib3.connectionpool - DEBUG - Starting new HTTPS connection (1): de.yuntech.poc.com:3443
2024-09-25 13:16:12 - urllib3.connectionpool - DEBUG - https://de.yuntech.poc.com:3443 "POST /agentfido/login/begin HTTP/1.1" 200 559
2024-09-25 13:16:23 - urllib3.connectionpool - DEBUG - Starting new HTTPS connection (1): de.yuntech.poc.com:3443
2024-09-25 13:16:23 - urllib3.connectionpool - DEBUG - https://de.yuntech.poc.com:3443 "POST /agentfido/login/complete HTTP/1.1" 200 45
