2024-08-13 19:16:30 - MyLogger - DEBUG - gRPC Server started on port 50051
2024-08-13 19:18:35 - urllib3.connectionpool - DEBUG - Starting new HTTP connection (1): de.yunpoc.edu.tw:3000
2024-08-13 19:18:35 - urllib3.connectionpool - DEBUG - http://de.yunpoc.edu.tw:3000 "POST /fido2/login/begin HTTP/1.1" 200 648
2024-08-13 19:18:42 - urllib3.connectionpool - DEBUG - Starting new HTTP connection (1): de.yunpoc.edu.tw:3000
2024-08-13 19:18:42 - urllib3.connectionpool - DEBUG - http://de.yunpoc.edu.tw:3000 "POST /fido2/login/complete HTTP/1.1" 200 22
2024-08-13 19:18:42 - grpc._server - ERROR - Exception calling application: 'data'
Traceback (most recent call last):
  File "/home/yunpep/non_web_protocal_zta/PEP/server/index/myvenv/lib/python3.12/site-packages/grpc/_server.py", line 609, in _call_behavior
    response_or_iterator = behavior(argument, context)
                           ^^^^^^^^^^^^^^^^^^^^^^^^^^^
  File "/home/yunpep/non_web_protocal_zta/PEP/server/index/grpc_server.py", line 146, in LoginComplete
    return credentials_pb2.Message(msg=message['data'])
                                       ~~~~~~~^^^^^^^^
KeyError: 'data'
2024-08-13 19:19:11 - urllib3.connectionpool - DEBUG - Starting new HTTP connection (1): de.yunpoc.edu.tw:3000
2024-08-13 19:19:11 - urllib3.connectionpool - DEBUG - http://de.yunpoc.edu.tw:3000 "POST /fido2/login/begin HTTP/1.1" 200 648
2024-08-13 19:19:19 - urllib3.connectionpool - DEBUG - Starting new HTTP connection (1): de.yunpoc.edu.tw:3000
2024-08-13 19:19:19 - urllib3.connectionpool - DEBUG - http://de.yunpoc.edu.tw:3000 "POST /fido2/login/complete HTTP/1.1" 200 22
2024-08-13 19:19:19 - grpc._server - ERROR - Exception calling application: 'data'
Traceback (most recent call last):
  File "/home/yunpep/non_web_protocal_zta/PEP/server/index/myvenv/lib/python3.12/site-packages/grpc/_server.py", line 609, in _call_behavior
    response_or_iterator = behavior(argument, context)
                           ^^^^^^^^^^^^^^^^^^^^^^^^^^^
  File "/home/yunpep/non_web_protocal_zta/PEP/server/index/grpc_server.py", line 146, in LoginComplete
    return credentials_pb2.Message(msg=message['data'])
                                       ~~~~~~~^^^^^^^^
KeyError: 'data'
2024-08-13 19:20:21 - urllib3.connectionpool - DEBUG - Starting new HTTP connection (1): de.yunpoc.edu.tw:3000
2024-08-13 19:20:21 - urllib3.connectionpool - DEBUG - http://de.yunpoc.edu.tw:3000 "POST /fido2/login/begin HTTP/1.1" 200 648
2024-08-13 19:20:29 - urllib3.connectionpool - DEBUG - Starting new HTTP connection (1): de.yunpoc.edu.tw:3000
2024-08-13 19:20:29 - urllib3.connectionpool - DEBUG - http://de.yunpoc.edu.tw:3000 "POST /fido2/login/complete HTTP/1.1" 200 43
2024-08-13 19:21:21 - urllib3.connectionpool - DEBUG - Starting new HTTP connection (1): de.yunpoc.edu.tw:3000
2024-08-13 19:21:21 - urllib3.connectionpool - DEBUG - http://de.yunpoc.edu.tw:3000 "POST /fido2/login/begin HTTP/1.1" 200 648
2024-08-13 19:21:29 - urllib3.connectionpool - DEBUG - Starting new HTTP connection (1): de.yunpoc.edu.tw:3000
2024-08-13 19:21:29 - urllib3.connectionpool - DEBUG - http://de.yunpoc.edu.tw:3000 "POST /fido2/login/complete HTTP/1.1" 500 64
2024-08-13 19:21:29 - grpc._server - ERROR - Exception calling application: 'data'
Traceback (most recent call last):
  File "/home/yunpep/non_web_protocal_zta/PEP/server/index/myvenv/lib/python3.12/site-packages/grpc/_server.py", line 609, in _call_behavior
    response_or_iterator = behavior(argument, context)
                           ^^^^^^^^^^^^^^^^^^^^^^^^^^^
  File "/home/yunpep/non_web_protocal_zta/PEP/server/index/grpc_server.py", line 146, in LoginComplete
    return credentials_pb2.Message(msg=message['data'])
                                       ~~~~~~~^^^^^^^^
KeyError: 'data'
2024-08-13 19:22:18 - urllib3.connectionpool - DEBUG - Starting new HTTP connection (1): de.yunpoc.edu.tw:3000
2024-08-13 19:22:18 - urllib3.connectionpool - DEBUG - http://de.yunpoc.edu.tw:3000 "POST /fido2/login/begin HTTP/1.1" 200 648
2024-08-13 19:22:29 - urllib3.connectionpool - DEBUG - Starting new HTTP connection (1): de.yunpoc.edu.tw:3000
2024-08-13 19:22:29 - urllib3.connectionpool - DEBUG - http://de.yunpoc.edu.tw:3000 "POST /fido2/login/complete HTTP/1.1" 200 43
2024-08-13 19:24:07 - urllib3.connectionpool - DEBUG - Starting new HTTP connection (1): de.yunpoc.edu.tw:3000
2024-08-13 19:24:07 - urllib3.connectionpool - DEBUG - http://de.yunpoc.edu.tw:3000 "POST /fido2/login/begin HTTP/1.1" 200 648
2024-08-13 19:24:14 - urllib3.connectionpool - DEBUG - Starting new HTTP connection (1): de.yunpoc.edu.tw:3000
2024-08-13 19:24:14 - urllib3.connectionpool - DEBUG - http://de.yunpoc.edu.tw:3000 "POST /fido2/login/complete HTTP/1.1" 200 43
2024-08-13 19:25:05 - urllib3.connectionpool - DEBUG - Starting new HTTP connection (1): de.yunpoc.edu.tw:3000
2024-08-13 19:25:05 - urllib3.connectionpool - DEBUG - http://de.yunpoc.edu.tw:3000 "POST /fido2/login/begin HTTP/1.1" 200 648
2024-08-13 19:25:12 - urllib3.connectionpool - DEBUG - Starting new HTTP connection (1): de.yunpoc.edu.tw:3000
2024-08-13 19:25:12 - urllib3.connectionpool - DEBUG - http://de.yunpoc.edu.tw:3000 "POST /fido2/login/complete HTTP/1.1" 200 43
2024-08-13 19:26:53 - urllib3.connectionpool - DEBUG - Starting new HTTP connection (1): de.yunpoc.edu.tw:3000
2024-08-13 19:26:53 - urllib3.connectionpool - DEBUG - http://de.yunpoc.edu.tw:3000 "POST /fido2/login/begin HTTP/1.1" 200 648
2024-08-13 19:27:04 - urllib3.connectionpool - DEBUG - Starting new HTTP connection (1): de.yunpoc.edu.tw:3000
2024-08-13 19:27:04 - urllib3.connectionpool - DEBUG - http://de.yunpoc.edu.tw:3000 "POST /fido2/login/complete HTTP/1.1" 200 43
2024-08-13 19:28:27 - urllib3.connectionpool - DEBUG - Starting new HTTP connection (1): de.yunpoc.edu.tw:3000
2024-08-13 19:28:27 - urllib3.connectionpool - DEBUG - http://de.yunpoc.edu.tw:3000 "POST /fido2/login/begin HTTP/1.1" 200 648
2024-08-13 19:29:19 - urllib3.connectionpool - DEBUG - Starting new HTTP connection (1): de.yunpoc.edu.tw:3000
2024-08-13 19:29:19 - urllib3.connectionpool - DEBUG - http://de.yunpoc.edu.tw:3000 "POST /fido2/login/begin HTTP/1.1" 200 648
2024-08-13 19:29:26 - urllib3.connectionpool - DEBUG - Starting new HTTP connection (1): de.yunpoc.edu.tw:3000
2024-08-13 19:29:26 - urllib3.connectionpool - DEBUG - http://de.yunpoc.edu.tw:3000 "POST /fido2/login/complete HTTP/1.1" 500 64
2024-08-13 19:29:26 - grpc._server - ERROR - Exception calling application: 'data'
Traceback (most recent call last):
  File "/home/yunpep/non_web_protocal_zta/PEP/server/index/myvenv/lib/python3.12/site-packages/grpc/_server.py", line 609, in _call_behavior
    response_or_iterator = behavior(argument, context)
                           ^^^^^^^^^^^^^^^^^^^^^^^^^^^
  File "/home/yunpep/non_web_protocal_zta/PEP/server/index/grpc_server.py", line 146, in LoginComplete
    return credentials_pb2.Message(msg=message['data'])
                                       ~~~~~~~^^^^^^^^
KeyError: 'data'
2024-08-13 19:30:11 - urllib3.connectionpool - DEBUG - Starting new HTTP connection (1): de.yunpoc.edu.tw:3000
2024-08-13 19:30:11 - urllib3.connectionpool - DEBUG - http://de.yunpoc.edu.tw:3000 "POST /fido2/login/begin HTTP/1.1" 200 648
2024-08-13 19:30:19 - urllib3.connectionpool - DEBUG - Starting new HTTP connection (1): de.yunpoc.edu.tw:3000
2024-08-13 19:30:19 - urllib3.connectionpool - DEBUG - http://de.yunpoc.edu.tw:3000 "POST /fido2/login/complete HTTP/1.1" 200 43
2024-08-13 19:36:31 - urllib3.connectionpool - DEBUG - Starting new HTTP connection (1): de.yunpoc.edu.tw:3000
2024-08-13 19:36:31 - urllib3.connectionpool - DEBUG - http://de.yunpoc.edu.tw:3000 "POST /fido2/login/begin HTTP/1.1" 200 648
2024-08-13 19:36:39 - urllib3.connectionpool - DEBUG - Starting new HTTP connection (1): de.yunpoc.edu.tw:3000
2024-08-13 19:36:39 - urllib3.connectionpool - DEBUG - http://de.yunpoc.edu.tw:3000 "POST /fido2/login/complete HTTP/1.1" 500 64
2024-08-13 19:36:39 - grpc._server - ERROR - Exception calling application: 'data'
Traceback (most recent call last):
  File "/home/yunpep/non_web_protocal_zta/PEP/server/index/myvenv/lib/python3.12/site-packages/grpc/_server.py", line 609, in _call_behavior
    response_or_iterator = behavior(argument, context)
                           ^^^^^^^^^^^^^^^^^^^^^^^^^^^
  File "/home/yunpep/non_web_protocal_zta/PEP/server/index/grpc_server.py", line 146, in LoginComplete
    return credentials_pb2.Message(msg=message['data'])
                                       ~~~~~~~^^^^^^^^
KeyError: 'data'
2024-08-13 19:40:32 - urllib3.connectionpool - DEBUG - Starting new HTTP connection (1): de.yunpoc.edu.tw:3000
2024-08-13 19:40:32 - urllib3.connectionpool - DEBUG - http://de.yunpoc.edu.tw:3000 "POST /fido2/login/begin HTTP/1.1" 200 648
2024-08-13 19:40:40 - urllib3.connectionpool - DEBUG - Starting new HTTP connection (1): de.yunpoc.edu.tw:3000
2024-08-13 19:40:40 - urllib3.connectionpool - DEBUG - http://de.yunpoc.edu.tw:3000 "POST /fido2/login/complete HTTP/1.1" 500 64
2024-08-13 19:40:40 - grpc._server - ERROR - Exception calling application: 'data'
Traceback (most recent call last):
  File "/home/yunpep/non_web_protocal_zta/PEP/server/index/myvenv/lib/python3.12/site-packages/grpc/_server.py", line 609, in _call_behavior
    response_or_iterator = behavior(argument, context)
                           ^^^^^^^^^^^^^^^^^^^^^^^^^^^
  File "/home/yunpep/non_web_protocal_zta/PEP/server/index/grpc_server.py", line 146, in LoginComplete
    return credentials_pb2.Message(msg=message['data'])
                                       ~~~~~~~^^^^^^^^
KeyError: 'data'
2024-08-13 19:42:04 - urllib3.connectionpool - DEBUG - Starting new HTTP connection (1): de.yunpoc.edu.tw:3000
2024-08-13 19:42:04 - urllib3.connectionpool - DEBUG - http://de.yunpoc.edu.tw:3000 "POST /fido2/login/begin HTTP/1.1" 200 648
2024-08-13 19:42:12 - urllib3.connectionpool - DEBUG - Starting new HTTP connection (1): de.yunpoc.edu.tw:3000
2024-08-13 19:42:12 - urllib3.connectionpool - DEBUG - http://de.yunpoc.edu.tw:3000 "POST /fido2/login/complete HTTP/1.1" 500 64
2024-08-13 19:42:12 - grpc._server - ERROR - Exception calling application: 'data'
Traceback (most recent call last):
  File "/home/yunpep/non_web_protocal_zta/PEP/server/index/myvenv/lib/python3.12/site-packages/grpc/_server.py", line 609, in _call_behavior
    response_or_iterator = behavior(argument, context)
                           ^^^^^^^^^^^^^^^^^^^^^^^^^^^
  File "/home/yunpep/non_web_protocal_zta/PEP/server/index/grpc_server.py", line 146, in LoginComplete
    return credentials_pb2.Message(msg=message['data'])
                                       ~~~~~~~^^^^^^^^
KeyError: 'data'
2024-08-13 19:43:44 - urllib3.connectionpool - DEBUG - Starting new HTTP connection (1): de.yunpoc.edu.tw:3000
2024-08-13 19:43:44 - urllib3.connectionpool - DEBUG - http://de.yunpoc.edu.tw:3000 "POST /fido2/login/begin HTTP/1.1" 200 648
2024-08-13 19:43:52 - urllib3.connectionpool - DEBUG - Starting new HTTP connection (1): de.yunpoc.edu.tw:3000
2024-08-13 19:43:52 - urllib3.connectionpool - DEBUG - http://de.yunpoc.edu.tw:3000 "POST /fido2/login/complete HTTP/1.1" 500 64
2024-08-13 19:43:52 - grpc._server - ERROR - Exception calling application: 'data'
Traceback (most recent call last):
  File "/home/yunpep/non_web_protocal_zta/PEP/server/index/myvenv/lib/python3.12/site-packages/grpc/_server.py", line 609, in _call_behavior
    response_or_iterator = behavior(argument, context)
                           ^^^^^^^^^^^^^^^^^^^^^^^^^^^
  File "/home/yunpep/non_web_protocal_zta/PEP/server/index/grpc_server.py", line 146, in LoginComplete
    return credentials_pb2.Message(msg=message['data'])
                                       ~~~~~~~^^^^^^^^
KeyError: 'data'
2024-08-13 19:44:52 - urllib3.connectionpool - DEBUG - Starting new HTTP connection (1): de.yunpoc.edu.tw:3000
2024-08-13 19:44:52 - urllib3.connectionpool - DEBUG - http://de.yunpoc.edu.tw:3000 "POST /fido2/login/begin HTTP/1.1" 200 648
2024-08-13 19:44:59 - urllib3.connectionpool - DEBUG - Starting new HTTP connection (1): de.yunpoc.edu.tw:3000
2024-08-13 19:44:59 - urllib3.connectionpool - DEBUG - http://de.yunpoc.edu.tw:3000 "POST /fido2/login/complete HTTP/1.1" 500 64
2024-08-13 19:44:59 - grpc._server - ERROR - Exception calling application: 'data'
Traceback (most recent call last):
  File "/home/yunpep/non_web_protocal_zta/PEP/server/index/myvenv/lib/python3.12/site-packages/grpc/_server.py", line 609, in _call_behavior
    response_or_iterator = behavior(argument, context)
                           ^^^^^^^^^^^^^^^^^^^^^^^^^^^
  File "/home/yunpep/non_web_protocal_zta/PEP/server/index/grpc_server.py", line 146, in LoginComplete
    return credentials_pb2.Message(msg=message['data'])
                                       ~~~~~~~^^^^^^^^
KeyError: 'data'
2024-08-13 19:47:52 - urllib3.connectionpool - DEBUG - Starting new HTTP connection (1): de.yunpoc.edu.tw:3000
2024-08-13 19:47:52 - urllib3.connectionpool - DEBUG - http://de.yunpoc.edu.tw:3000 "POST /fido2/login/begin HTTP/1.1" 200 648
2024-08-13 19:48:01 - urllib3.connectionpool - DEBUG - Starting new HTTP connection (1): de.yunpoc.edu.tw:3000
2024-08-13 19:48:01 - urllib3.connectionpool - DEBUG - http://de.yunpoc.edu.tw:3000 "POST /fido2/login/complete HTTP/1.1" 500 64
2024-08-13 19:48:01 - grpc._server - ERROR - Exception calling application: 'data'
Traceback (most recent call last):
  File "/home/yunpep/non_web_protocal_zta/PEP/server/index/myvenv/lib/python3.12/site-packages/grpc/_server.py", line 609, in _call_behavior
    response_or_iterator = behavior(argument, context)
                           ^^^^^^^^^^^^^^^^^^^^^^^^^^^
  File "/home/yunpep/non_web_protocal_zta/PEP/server/index/grpc_server.py", line 146, in LoginComplete
    return credentials_pb2.Message(msg=message['data'])
                                       ~~~~~~~^^^^^^^^
KeyError: 'data'
2024-08-13 19:48:42 - urllib3.connectionpool - DEBUG - Starting new HTTP connection (1): de.yunpoc.edu.tw:3000
2024-08-13 19:48:42 - urllib3.connectionpool - DEBUG - http://de.yunpoc.edu.tw:3000 "POST /fido2/login/begin HTTP/1.1" 200 648
2024-08-13 19:48:49 - urllib3.connectionpool - DEBUG - Starting new HTTP connection (1): de.yunpoc.edu.tw:3000
2024-08-13 19:48:49 - urllib3.connectionpool - DEBUG - http://de.yunpoc.edu.tw:3000 "POST /fido2/login/complete HTTP/1.1" 500 64
2024-08-13 19:48:49 - grpc._server - ERROR - Exception calling application: 'data'
Traceback (most recent call last):
  File "/home/yunpep/non_web_protocal_zta/PEP/server/index/myvenv/lib/python3.12/site-packages/grpc/_server.py", line 609, in _call_behavior
    response_or_iterator = behavior(argument, context)
                           ^^^^^^^^^^^^^^^^^^^^^^^^^^^
  File "/home/yunpep/non_web_protocal_zta/PEP/server/index/grpc_server.py", line 146, in LoginComplete
    return credentials_pb2.Message(msg=message['data'])
                                       ~~~~~~~^^^^^^^^
KeyError: 'data'
2024-08-13 19:52:24 - urllib3.connectionpool - DEBUG - Starting new HTTP connection (1): de.yunpoc.edu.tw:3000
2024-08-13 19:52:24 - urllib3.connectionpool - DEBUG - http://de.yunpoc.edu.tw:3000 "POST /fido2/login/begin HTTP/1.1" 200 648
2024-08-13 19:52:32 - urllib3.connectionpool - DEBUG - Starting new HTTP connection (1): de.yunpoc.edu.tw:3000
2024-08-13 19:52:32 - urllib3.connectionpool - DEBUG - http://de.yunpoc.edu.tw:3000 "POST /fido2/login/complete HTTP/1.1" 500 64
2024-08-13 19:52:32 - grpc._server - ERROR - Exception calling application: 'data'
Traceback (most recent call last):
  File "/home/yunpep/non_web_protocal_zta/PEP/server/index/myvenv/lib/python3.12/site-packages/grpc/_server.py", line 609, in _call_behavior
    response_or_iterator = behavior(argument, context)
                           ^^^^^^^^^^^^^^^^^^^^^^^^^^^
  File "/home/yunpep/non_web_protocal_zta/PEP/server/index/grpc_server.py", line 146, in LoginComplete
    return credentials_pb2.Message(msg=message['data'])
                                       ~~~~~~~^^^^^^^^
KeyError: 'data'
2024-08-13 19:53:05 - urllib3.connectionpool - DEBUG - Starting new HTTP connection (1): de.yunpoc.edu.tw:3000
2024-08-13 19:53:05 - urllib3.connectionpool - DEBUG - http://de.yunpoc.edu.tw:3000 "POST /fido2/login/begin HTTP/1.1" 200 648
2024-08-13 19:53:16 - urllib3.connectionpool - DEBUG - Starting new HTTP connection (1): de.yunpoc.edu.tw:3000
2024-08-13 19:53:16 - urllib3.connectionpool - DEBUG - http://de.yunpoc.edu.tw:3000 "POST /fido2/login/complete HTTP/1.1" 500 64
2024-08-13 19:53:16 - grpc._server - ERROR - Exception calling application: 'data'
Traceback (most recent call last):
  File "/home/yunpep/non_web_protocal_zta/PEP/server/index/myvenv/lib/python3.12/site-packages/grpc/_server.py", line 609, in _call_behavior
    response_or_iterator = behavior(argument, context)
                           ^^^^^^^^^^^^^^^^^^^^^^^^^^^
  File "/home/yunpep/non_web_protocal_zta/PEP/server/index/grpc_server.py", line 146, in LoginComplete
    return credentials_pb2.Message(msg=message['data'])
                                       ~~~~~~~^^^^^^^^
KeyError: 'data'
2024-08-13 19:55:03 - urllib3.connectionpool - DEBUG - Starting new HTTP connection (1): de.yunpoc.edu.tw:3000
2024-08-13 19:55:03 - urllib3.connectionpool - DEBUG - http://de.yunpoc.edu.tw:3000 "POST /fido2/login/begin HTTP/1.1" 200 648
2024-08-13 19:55:11 - urllib3.connectionpool - DEBUG - Starting new HTTP connection (1): de.yunpoc.edu.tw:3000
2024-08-13 19:55:11 - urllib3.connectionpool - DEBUG - http://de.yunpoc.edu.tw:3000 "POST /fido2/login/complete HTTP/1.1" 500 64
2024-08-13 19:55:11 - grpc._server - ERROR - Exception calling application: 'data'
Traceback (most recent call last):
  File "/home/yunpep/non_web_protocal_zta/PEP/server/index/myvenv/lib/python3.12/site-packages/grpc/_server.py", line 609, in _call_behavior
    response_or_iterator = behavior(argument, context)
                           ^^^^^^^^^^^^^^^^^^^^^^^^^^^
  File "/home/yunpep/non_web_protocal_zta/PEP/server/index/grpc_server.py", line 146, in LoginComplete
    return credentials_pb2.Message(msg=message['data'])
                                       ~~~~~~~^^^^^^^^
KeyError: 'data'
2024-08-13 19:55:33 - urllib3.connectionpool - DEBUG - Starting new HTTP connection (1): de.yunpoc.edu.tw:3000
2024-08-13 19:55:33 - urllib3.connectionpool - DEBUG - http://de.yunpoc.edu.tw:3000 "POST /fido2/login/begin HTTP/1.1" 200 648
2024-08-13 19:55:40 - urllib3.connectionpool - DEBUG - Starting new HTTP connection (1): de.yunpoc.edu.tw:3000
2024-08-13 19:55:40 - urllib3.connectionpool - DEBUG - http://de.yunpoc.edu.tw:3000 "POST /fido2/login/complete HTTP/1.1" 500 64
2024-08-13 19:55:40 - grpc._server - ERROR - Exception calling application: 'data'
Traceback (most recent call last):
  File "/home/yunpep/non_web_protocal_zta/PEP/server/index/myvenv/lib/python3.12/site-packages/grpc/_server.py", line 609, in _call_behavior
    response_or_iterator = behavior(argument, context)
                           ^^^^^^^^^^^^^^^^^^^^^^^^^^^
  File "/home/yunpep/non_web_protocal_zta/PEP/server/index/grpc_server.py", line 146, in LoginComplete
    return credentials_pb2.Message(msg=message['data'])
                                       ~~~~~~~^^^^^^^^
KeyError: 'data'
2024-08-13 19:59:36 - urllib3.connectionpool - DEBUG - Starting new HTTP connection (1): de.yunpoc.edu.tw:3000
2024-08-13 19:59:36 - urllib3.connectionpool - DEBUG - http://de.yunpoc.edu.tw:3000 "POST /fido2/login/begin HTTP/1.1" 200 648
2024-08-13 19:59:44 - urllib3.connectionpool - DEBUG - Starting new HTTP connection (1): de.yunpoc.edu.tw:3000
2024-08-13 19:59:44 - urllib3.connectionpool - DEBUG - http://de.yunpoc.edu.tw:3000 "POST /fido2/login/complete HTTP/1.1" 500 64
2024-08-13 19:59:44 - grpc._server - ERROR - Exception calling application: 'data'
Traceback (most recent call last):
  File "/home/yunpep/non_web_protocal_zta/PEP/server/index/myvenv/lib/python3.12/site-packages/grpc/_server.py", line 609, in _call_behavior
    response_or_iterator = behavior(argument, context)
                           ^^^^^^^^^^^^^^^^^^^^^^^^^^^
  File "/home/yunpep/non_web_protocal_zta/PEP/server/index/grpc_server.py", line 146, in LoginComplete
    return credentials_pb2.Message(msg=message['data'])
                                       ~~~~~~~^^^^^^^^
KeyError: 'data'
2024-08-13 20:02:22 - urllib3.connectionpool - DEBUG - Starting new HTTP connection (1): de.yunpoc.edu.tw:3000
2024-08-13 20:02:22 - urllib3.connectionpool - DEBUG - http://de.yunpoc.edu.tw:3000 "POST /fido2/login/begin HTTP/1.1" 200 648
2024-08-13 20:02:30 - urllib3.connectionpool - DEBUG - Starting new HTTP connection (1): de.yunpoc.edu.tw:3000
2024-08-13 20:02:30 - urllib3.connectionpool - DEBUG - http://de.yunpoc.edu.tw:3000 "POST /fido2/login/complete HTTP/1.1" 500 64
2024-08-13 20:02:30 - grpc._server - ERROR - Exception calling application: 'data'
Traceback (most recent call last):
  File "/home/yunpep/non_web_protocal_zta/PEP/server/index/myvenv/lib/python3.12/site-packages/grpc/_server.py", line 609, in _call_behavior
    response_or_iterator = behavior(argument, context)
                           ^^^^^^^^^^^^^^^^^^^^^^^^^^^
  File "/home/yunpep/non_web_protocal_zta/PEP/server/index/grpc_server.py", line 146, in LoginComplete
    return credentials_pb2.Message(msg=message['data'])
                                       ~~~~~~~^^^^^^^^
KeyError: 'data'
2024-08-13 20:05:26 - urllib3.connectionpool - DEBUG - Starting new HTTP connection (1): de.yunpoc.edu.tw:3000
2024-08-13 20:05:27 - urllib3.connectionpool - DEBUG - http://de.yunpoc.edu.tw:3000 "POST /fido2/login/begin HTTP/1.1" 200 648
2024-08-13 20:05:34 - urllib3.connectionpool - DEBUG - Starting new HTTP connection (1): de.yunpoc.edu.tw:3000
2024-08-13 20:05:34 - urllib3.connectionpool - DEBUG - http://de.yunpoc.edu.tw:3000 "POST /fido2/login/complete HTTP/1.1" 500 64
2024-08-13 20:05:34 - grpc._server - ERROR - Exception calling application: 'data'
Traceback (most recent call last):
  File "/home/yunpep/non_web_protocal_zta/PEP/server/index/myvenv/lib/python3.12/site-packages/grpc/_server.py", line 609, in _call_behavior
    response_or_iterator = behavior(argument, context)
                           ^^^^^^^^^^^^^^^^^^^^^^^^^^^
  File "/home/yunpep/non_web_protocal_zta/PEP/server/index/grpc_server.py", line 146, in LoginComplete
    return credentials_pb2.Message(msg=message['data'])
                                       ~~~~~~~^^^^^^^^
KeyError: 'data'
2024-08-13 20:07:14 - urllib3.connectionpool - DEBUG - Starting new HTTP connection (1): de.yunpoc.edu.tw:3000
2024-08-13 20:07:14 - urllib3.connectionpool - DEBUG - http://de.yunpoc.edu.tw:3000 "POST /fido2/login/begin HTTP/1.1" 200 648
2024-08-13 20:07:22 - urllib3.connectionpool - DEBUG - Starting new HTTP connection (1): de.yunpoc.edu.tw:3000
2024-08-13 20:07:22 - urllib3.connectionpool - DEBUG - http://de.yunpoc.edu.tw:3000 "POST /fido2/login/complete HTTP/1.1" 500 64
2024-08-13 20:07:22 - grpc._server - ERROR - Exception calling application: 'data'
Traceback (most recent call last):
  File "/home/yunpep/non_web_protocal_zta/PEP/server/index/myvenv/lib/python3.12/site-packages/grpc/_server.py", line 609, in _call_behavior
    response_or_iterator = behavior(argument, context)
                           ^^^^^^^^^^^^^^^^^^^^^^^^^^^
  File "/home/yunpep/non_web_protocal_zta/PEP/server/index/grpc_server.py", line 146, in LoginComplete
    return credentials_pb2.Message(msg=message['data'])
                                       ~~~~~~~^^^^^^^^
KeyError: 'data'
2024-08-13 20:08:54 - urllib3.connectionpool - DEBUG - Starting new HTTP connection (1): de.yunpoc.edu.tw:3000
2024-08-13 20:08:54 - urllib3.connectionpool - DEBUG - http://de.yunpoc.edu.tw:3000 "POST /fido2/login/begin HTTP/1.1" 200 648
2024-08-13 20:09:02 - urllib3.connectionpool - DEBUG - Starting new HTTP connection (1): de.yunpoc.edu.tw:3000
2024-08-13 20:09:02 - urllib3.connectionpool - DEBUG - http://de.yunpoc.edu.tw:3000 "POST /fido2/login/complete HTTP/1.1" 500 64
2024-08-13 20:09:02 - grpc._server - ERROR - Exception calling application: 'data'
Traceback (most recent call last):
  File "/home/yunpep/non_web_protocal_zta/PEP/server/index/myvenv/lib/python3.12/site-packages/grpc/_server.py", line 609, in _call_behavior
    response_or_iterator = behavior(argument, context)
                           ^^^^^^^^^^^^^^^^^^^^^^^^^^^
  File "/home/yunpep/non_web_protocal_zta/PEP/server/index/grpc_server.py", line 146, in LoginComplete
    return credentials_pb2.Message(msg=message['data'])
                                       ~~~~~~~^^^^^^^^
KeyError: 'data'
2024-08-13 20:09:39 - urllib3.connectionpool - DEBUG - Starting new HTTP connection (1): de.yunpoc.edu.tw:3000
2024-08-13 20:09:39 - urllib3.connectionpool - DEBUG - http://de.yunpoc.edu.tw:3000 "POST /fido2/login/begin HTTP/1.1" 200 648
2024-08-13 20:09:47 - urllib3.connectionpool - DEBUG - Starting new HTTP connection (1): de.yunpoc.edu.tw:3000
2024-08-13 20:09:47 - urllib3.connectionpool - DEBUG - http://de.yunpoc.edu.tw:3000 "POST /fido2/login/complete HTTP/1.1" 500 64
2024-08-13 20:09:47 - grpc._server - ERROR - Exception calling application: 'data'
Traceback (most recent call last):
  File "/home/yunpep/non_web_protocal_zta/PEP/server/index/myvenv/lib/python3.12/site-packages/grpc/_server.py", line 609, in _call_behavior
    response_or_iterator = behavior(argument, context)
                           ^^^^^^^^^^^^^^^^^^^^^^^^^^^
  File "/home/yunpep/non_web_protocal_zta/PEP/server/index/grpc_server.py", line 146, in LoginComplete
    return credentials_pb2.Message(msg=message['data'])
                                       ~~~~~~~^^^^^^^^
KeyError: 'data'
2024-08-13 20:11:33 - urllib3.connectionpool - DEBUG - Starting new HTTP connection (1): de.yunpoc.edu.tw:3000
2024-08-13 20:11:33 - urllib3.connectionpool - DEBUG - http://de.yunpoc.edu.tw:3000 "POST /fido2/login/begin HTTP/1.1" 200 648
2024-08-13 20:11:40 - urllib3.connectionpool - DEBUG - Starting new HTTP connection (1): de.yunpoc.edu.tw:3000
2024-08-13 20:11:40 - urllib3.connectionpool - DEBUG - http://de.yunpoc.edu.tw:3000 "POST /fido2/login/complete HTTP/1.1" 500 64
2024-08-13 20:11:40 - grpc._server - ERROR - Exception calling application: 'data'
Traceback (most recent call last):
  File "/home/yunpep/non_web_protocal_zta/PEP/server/index/myvenv/lib/python3.12/site-packages/grpc/_server.py", line 609, in _call_behavior
    response_or_iterator = behavior(argument, context)
                           ^^^^^^^^^^^^^^^^^^^^^^^^^^^
  File "/home/yunpep/non_web_protocal_zta/PEP/server/index/grpc_server.py", line 146, in LoginComplete
    return credentials_pb2.Message(msg=message['data'])
                                       ~~~~~~~^^^^^^^^
KeyError: 'data'
2024-08-13 20:16:11 - urllib3.connectionpool - DEBUG - Starting new HTTP connection (1): de.yunpoc.edu.tw:3000
2024-08-13 20:16:11 - urllib3.connectionpool - DEBUG - http://de.yunpoc.edu.tw:3000 "POST /fido2/login/begin HTTP/1.1" 200 648
2024-08-13 20:16:19 - urllib3.connectionpool - DEBUG - Starting new HTTP connection (1): de.yunpoc.edu.tw:3000
2024-08-13 20:16:19 - urllib3.connectionpool - DEBUG - http://de.yunpoc.edu.tw:3000 "POST /fido2/login/complete HTTP/1.1" 500 64
2024-08-13 20:16:19 - grpc._server - ERROR - Exception calling application: 'data'
Traceback (most recent call last):
  File "/home/yunpep/non_web_protocal_zta/PEP/server/index/myvenv/lib/python3.12/site-packages/grpc/_server.py", line 609, in _call_behavior
    response_or_iterator = behavior(argument, context)
                           ^^^^^^^^^^^^^^^^^^^^^^^^^^^
  File "/home/yunpep/non_web_protocal_zta/PEP/server/index/grpc_server.py", line 146, in LoginComplete
    return credentials_pb2.Message(msg=message['data'])
                                       ~~~~~~~^^^^^^^^
KeyError: 'data'
2024-08-13 20:16:52 - urllib3.connectionpool - DEBUG - Starting new HTTP connection (1): de.yunpoc.edu.tw:3000
2024-08-13 20:16:52 - urllib3.connectionpool - DEBUG - http://de.yunpoc.edu.tw:3000 "POST /fido2/login/begin HTTP/1.1" 200 648
2024-08-13 20:17:00 - urllib3.connectionpool - DEBUG - Starting new HTTP connection (1): de.yunpoc.edu.tw:3000
2024-08-13 20:17:00 - urllib3.connectionpool - DEBUG - http://de.yunpoc.edu.tw:3000 "POST /fido2/login/complete HTTP/1.1" 500 64
2024-08-13 20:17:00 - grpc._server - ERROR - Exception calling application: 'data'
Traceback (most recent call last):
  File "/home/yunpep/non_web_protocal_zta/PEP/server/index/myvenv/lib/python3.12/site-packages/grpc/_server.py", line 609, in _call_behavior
    response_or_iterator = behavior(argument, context)
                           ^^^^^^^^^^^^^^^^^^^^^^^^^^^
  File "/home/yunpep/non_web_protocal_zta/PEP/server/index/grpc_server.py", line 146, in LoginComplete
    return credentials_pb2.Message(msg=message['data'])
                                       ~~~~~~~^^^^^^^^
KeyError: 'data'
2024-08-13 20:19:43 - urllib3.connectionpool - DEBUG - Starting new HTTP connection (1): de.yunpoc.edu.tw:3000
2024-08-13 20:19:43 - urllib3.connectionpool - DEBUG - http://de.yunpoc.edu.tw:3000 "POST /fido2/login/begin HTTP/1.1" 200 648
2024-08-13 20:19:51 - urllib3.connectionpool - DEBUG - Starting new HTTP connection (1): de.yunpoc.edu.tw:3000
2024-08-13 20:19:51 - urllib3.connectionpool - DEBUG - http://de.yunpoc.edu.tw:3000 "POST /fido2/login/complete HTTP/1.1" 500 64
2024-08-13 20:19:51 - grpc._server - ERROR - Exception calling application: 'data'
Traceback (most recent call last):
  File "/home/yunpep/non_web_protocal_zta/PEP/server/index/myvenv/lib/python3.12/site-packages/grpc/_server.py", line 609, in _call_behavior
    response_or_iterator = behavior(argument, context)
                           ^^^^^^^^^^^^^^^^^^^^^^^^^^^
  File "/home/yunpep/non_web_protocal_zta/PEP/server/index/grpc_server.py", line 146, in LoginComplete
    return credentials_pb2.Message(msg=message['data'])
                                       ~~~~~~~^^^^^^^^
KeyError: 'data'
2024-08-13 20:22:18 - urllib3.connectionpool - DEBUG - Starting new HTTP connection (1): de.yunpoc.edu.tw:3000
2024-08-13 20:22:18 - urllib3.connectionpool - DEBUG - http://de.yunpoc.edu.tw:3000 "POST /fido2/login/begin HTTP/1.1" 200 648
2024-08-13 20:22:29 - urllib3.connectionpool - DEBUG - Starting new HTTP connection (1): de.yunpoc.edu.tw:3000
2024-08-13 20:22:29 - urllib3.connectionpool - DEBUG - http://de.yunpoc.edu.tw:3000 "POST /fido2/login/complete HTTP/1.1" 500 64
2024-08-13 20:22:29 - grpc._server - ERROR - Exception calling application: 'data'
Traceback (most recent call last):
  File "/home/yunpep/non_web_protocal_zta/PEP/server/index/myvenv/lib/python3.12/site-packages/grpc/_server.py", line 609, in _call_behavior
    response_or_iterator = behavior(argument, context)
                           ^^^^^^^^^^^^^^^^^^^^^^^^^^^
  File "/home/yunpep/non_web_protocal_zta/PEP/server/index/grpc_server.py", line 146, in LoginComplete
    return credentials_pb2.Message(msg=message['data'])
                                       ~~~~~~~^^^^^^^^
KeyError: 'data'
2024-08-13 20:23:56 - urllib3.connectionpool - DEBUG - Starting new HTTP connection (1): de.yunpoc.edu.tw:3000
2024-08-13 20:23:56 - urllib3.connectionpool - DEBUG - http://de.yunpoc.edu.tw:3000 "POST /fido2/login/begin HTTP/1.1" 200 648
2024-08-13 20:24:04 - urllib3.connectionpool - DEBUG - Starting new HTTP connection (1): de.yunpoc.edu.tw:3000
2024-08-13 20:24:04 - urllib3.connectionpool - DEBUG - http://de.yunpoc.edu.tw:3000 "POST /fido2/login/complete HTTP/1.1" 500 64
2024-08-13 20:24:04 - grpc._server - ERROR - Exception calling application: 'data'
Traceback (most recent call last):
  File "/home/yunpep/non_web_protocal_zta/PEP/server/index/myvenv/lib/python3.12/site-packages/grpc/_server.py", line 609, in _call_behavior
    response_or_iterator = behavior(argument, context)
                           ^^^^^^^^^^^^^^^^^^^^^^^^^^^
  File "/home/yunpep/non_web_protocal_zta/PEP/server/index/grpc_server.py", line 146, in LoginComplete
    return credentials_pb2.Message(msg=message['data'])
                                       ~~~~~~~^^^^^^^^
KeyError: 'data'
2024-08-13 20:24:45 - urllib3.connectionpool - DEBUG - Starting new HTTP connection (1): de.yunpoc.edu.tw:3000
2024-08-13 20:24:46 - urllib3.connectionpool - DEBUG - http://de.yunpoc.edu.tw:3000 "POST /fido2/login/begin HTTP/1.1" 200 648
2024-08-13 20:24:54 - urllib3.connectionpool - DEBUG - Starting new HTTP connection (1): de.yunpoc.edu.tw:3000
2024-08-13 20:24:54 - urllib3.connectionpool - DEBUG - http://de.yunpoc.edu.tw:3000 "POST /fido2/login/complete HTTP/1.1" 500 64
2024-08-13 20:24:54 - grpc._server - ERROR - Exception calling application: 'data'
Traceback (most recent call last):
  File "/home/yunpep/non_web_protocal_zta/PEP/server/index/myvenv/lib/python3.12/site-packages/grpc/_server.py", line 609, in _call_behavior
    response_or_iterator = behavior(argument, context)
                           ^^^^^^^^^^^^^^^^^^^^^^^^^^^
  File "/home/yunpep/non_web_protocal_zta/PEP/server/index/grpc_server.py", line 146, in LoginComplete
    return credentials_pb2.Message(msg=message['data'])
                                       ~~~~~~~^^^^^^^^
KeyError: 'data'
2024-08-13 20:29:20 - urllib3.connectionpool - DEBUG - Starting new HTTP connection (1): de.yunpoc.edu.tw:3000
2024-08-13 20:29:20 - urllib3.connectionpool - DEBUG - http://de.yunpoc.edu.tw:3000 "POST /fido2/login/begin HTTP/1.1" 200 648
2024-08-13 20:29:28 - urllib3.connectionpool - DEBUG - Starting new HTTP connection (1): de.yunpoc.edu.tw:3000
2024-08-13 20:29:28 - urllib3.connectionpool - DEBUG - http://de.yunpoc.edu.tw:3000 "POST /fido2/login/complete HTTP/1.1" 500 64
2024-08-13 20:29:28 - grpc._server - ERROR - Exception calling application: 'data'
Traceback (most recent call last):
  File "/home/yunpep/non_web_protocal_zta/PEP/server/index/myvenv/lib/python3.12/site-packages/grpc/_server.py", line 609, in _call_behavior
    response_or_iterator = behavior(argument, context)
                           ^^^^^^^^^^^^^^^^^^^^^^^^^^^
  File "/home/yunpep/non_web_protocal_zta/PEP/server/index/grpc_server.py", line 146, in LoginComplete
    return credentials_pb2.Message(msg=message['data'])
                                       ~~~~~~~^^^^^^^^
KeyError: 'data'
2024-08-13 20:31:28 - urllib3.connectionpool - DEBUG - Starting new HTTP connection (1): de.yunpoc.edu.tw:3000
2024-08-13 20:31:28 - urllib3.connectionpool - DEBUG - http://de.yunpoc.edu.tw:3000 "POST /fido2/login/begin HTTP/1.1" 200 648
2024-08-13 20:31:35 - urllib3.connectionpool - DEBUG - Starting new HTTP connection (1): de.yunpoc.edu.tw:3000
2024-08-13 20:31:35 - urllib3.connectionpool - DEBUG - http://de.yunpoc.edu.tw:3000 "POST /fido2/login/complete HTTP/1.1" 500 64
2024-08-13 20:31:35 - grpc._server - ERROR - Exception calling application: 'data'
Traceback (most recent call last):
  File "/home/yunpep/non_web_protocal_zta/PEP/server/index/myvenv/lib/python3.12/site-packages/grpc/_server.py", line 609, in _call_behavior
    response_or_iterator = behavior(argument, context)
                           ^^^^^^^^^^^^^^^^^^^^^^^^^^^
  File "/home/yunpep/non_web_protocal_zta/PEP/server/index/grpc_server.py", line 146, in LoginComplete
    return credentials_pb2.Message(msg=message['data'])
                                       ~~~~~~~^^^^^^^^
KeyError: 'data'
2024-08-13 20:33:24 - urllib3.connectionpool - DEBUG - Starting new HTTP connection (1): de.yunpoc.edu.tw:3000
2024-08-13 20:33:24 - urllib3.connectionpool - DEBUG - http://de.yunpoc.edu.tw:3000 "POST /fido2/login/begin HTTP/1.1" 200 648
2024-08-13 20:33:32 - urllib3.connectionpool - DEBUG - Starting new HTTP connection (1): de.yunpoc.edu.tw:3000
2024-08-13 20:33:32 - urllib3.connectionpool - DEBUG - http://de.yunpoc.edu.tw:3000 "POST /fido2/login/complete HTTP/1.1" 500 64
2024-08-13 20:33:32 - grpc._server - ERROR - Exception calling application: 'data'
Traceback (most recent call last):
  File "/home/yunpep/non_web_protocal_zta/PEP/server/index/myvenv/lib/python3.12/site-packages/grpc/_server.py", line 609, in _call_behavior
    response_or_iterator = behavior(argument, context)
                           ^^^^^^^^^^^^^^^^^^^^^^^^^^^
  File "/home/yunpep/non_web_protocal_zta/PEP/server/index/grpc_server.py", line 146, in LoginComplete
    return credentials_pb2.Message(msg=message['data'])
                                       ~~~~~~~^^^^^^^^
KeyError: 'data'
2024-08-13 20:35:26 - urllib3.connectionpool - DEBUG - Starting new HTTP connection (1): de.yunpoc.edu.tw:3000
2024-08-13 20:35:26 - urllib3.connectionpool - DEBUG - http://de.yunpoc.edu.tw:3000 "POST /fido2/login/begin HTTP/1.1" 200 648
2024-08-13 20:35:36 - urllib3.connectionpool - DEBUG - Starting new HTTP connection (1): de.yunpoc.edu.tw:3000
2024-08-13 20:35:36 - urllib3.connectionpool - DEBUG - http://de.yunpoc.edu.tw:3000 "POST /fido2/login/complete HTTP/1.1" 500 64
2024-08-13 20:35:36 - grpc._server - ERROR - Exception calling application: 'data'
Traceback (most recent call last):
  File "/home/yunpep/non_web_protocal_zta/PEP/server/index/myvenv/lib/python3.12/site-packages/grpc/_server.py", line 609, in _call_behavior
    response_or_iterator = behavior(argument, context)
                           ^^^^^^^^^^^^^^^^^^^^^^^^^^^
  File "/home/yunpep/non_web_protocal_zta/PEP/server/index/grpc_server.py", line 146, in LoginComplete
    return credentials_pb2.Message(msg=message['data'])
                                       ~~~~~~~^^^^^^^^
KeyError: 'data'
2024-08-13 20:36:16 - urllib3.connectionpool - DEBUG - Starting new HTTP connection (1): de.yunpoc.edu.tw:3000
2024-08-13 20:36:16 - urllib3.connectionpool - DEBUG - http://de.yunpoc.edu.tw:3000 "POST /fido2/login/begin HTTP/1.1" 200 648
2024-08-13 20:36:26 - urllib3.connectionpool - DEBUG - Starting new HTTP connection (1): de.yunpoc.edu.tw:3000
2024-08-13 20:36:26 - urllib3.connectionpool - DEBUG - http://de.yunpoc.edu.tw:3000 "POST /fido2/login/complete HTTP/1.1" 500 64
2024-08-13 20:36:26 - grpc._server - ERROR - Exception calling application: 'data'
Traceback (most recent call last):
  File "/home/yunpep/non_web_protocal_zta/PEP/server/index/myvenv/lib/python3.12/site-packages/grpc/_server.py", line 609, in _call_behavior
    response_or_iterator = behavior(argument, context)
                           ^^^^^^^^^^^^^^^^^^^^^^^^^^^
  File "/home/yunpep/non_web_protocal_zta/PEP/server/index/grpc_server.py", line 146, in LoginComplete
    return credentials_pb2.Message(msg=message['data'])
                                       ~~~~~~~^^^^^^^^
KeyError: 'data'
2024-08-13 20:36:52 - urllib3.connectionpool - DEBUG - Starting new HTTP connection (1): de.yunpoc.edu.tw:3000
2024-08-13 20:36:52 - urllib3.connectionpool - DEBUG - http://de.yunpoc.edu.tw:3000 "POST /fido2/login/begin HTTP/1.1" 200 648
2024-08-13 20:37:00 - urllib3.connectionpool - DEBUG - Starting new HTTP connection (1): de.yunpoc.edu.tw:3000
2024-08-13 20:37:00 - urllib3.connectionpool - DEBUG - http://de.yunpoc.edu.tw:3000 "POST /fido2/login/complete HTTP/1.1" 500 64
2024-08-13 20:37:00 - grpc._server - ERROR - Exception calling application: 'data'
Traceback (most recent call last):
  File "/home/yunpep/non_web_protocal_zta/PEP/server/index/myvenv/lib/python3.12/site-packages/grpc/_server.py", line 609, in _call_behavior
    response_or_iterator = behavior(argument, context)
                           ^^^^^^^^^^^^^^^^^^^^^^^^^^^
  File "/home/yunpep/non_web_protocal_zta/PEP/server/index/grpc_server.py", line 146, in LoginComplete
    return credentials_pb2.Message(msg=message['data'])
                                       ~~~~~~~^^^^^^^^
KeyError: 'data'
2024-08-13 20:37:59 - urllib3.connectionpool - DEBUG - Starting new HTTP connection (1): de.yunpoc.edu.tw:3000
2024-08-13 20:37:59 - urllib3.connectionpool - DEBUG - http://de.yunpoc.edu.tw:3000 "POST /fido2/login/begin HTTP/1.1" 200 648
2024-08-13 20:38:07 - urllib3.connectionpool - DEBUG - Starting new HTTP connection (1): de.yunpoc.edu.tw:3000
2024-08-13 20:38:07 - urllib3.connectionpool - DEBUG - http://de.yunpoc.edu.tw:3000 "POST /fido2/login/complete HTTP/1.1" 500 64
2024-08-13 20:38:07 - grpc._server - ERROR - Exception calling application: 'data'
Traceback (most recent call last):
  File "/home/yunpep/non_web_protocal_zta/PEP/server/index/myvenv/lib/python3.12/site-packages/grpc/_server.py", line 609, in _call_behavior
    response_or_iterator = behavior(argument, context)
                           ^^^^^^^^^^^^^^^^^^^^^^^^^^^
  File "/home/yunpep/non_web_protocal_zta/PEP/server/index/grpc_server.py", line 146, in LoginComplete
    return credentials_pb2.Message(msg=message['data'])
                                       ~~~~~~~^^^^^^^^
KeyError: 'data'
2024-08-13 20:38:30 - urllib3.connectionpool - DEBUG - Starting new HTTP connection (1): de.yunpoc.edu.tw:3000
2024-08-13 20:38:30 - urllib3.connectionpool - DEBUG - http://de.yunpoc.edu.tw:3000 "POST /fido2/login/begin HTTP/1.1" 200 648
2024-08-13 20:38:38 - urllib3.connectionpool - DEBUG - Starting new HTTP connection (1): de.yunpoc.edu.tw:3000
2024-08-13 20:38:38 - urllib3.connectionpool - DEBUG - http://de.yunpoc.edu.tw:3000 "POST /fido2/login/complete HTTP/1.1" 500 64
2024-08-13 20:38:38 - grpc._server - ERROR - Exception calling application: 'data'
Traceback (most recent call last):
  File "/home/yunpep/non_web_protocal_zta/PEP/server/index/myvenv/lib/python3.12/site-packages/grpc/_server.py", line 609, in _call_behavior
    response_or_iterator = behavior(argument, context)
                           ^^^^^^^^^^^^^^^^^^^^^^^^^^^
  File "/home/yunpep/non_web_protocal_zta/PEP/server/index/grpc_server.py", line 146, in LoginComplete
    return credentials_pb2.Message(msg=message['data'])
                                       ~~~~~~~^^^^^^^^
KeyError: 'data'
2024-08-13 20:38:58 - urllib3.connectionpool - DEBUG - Starting new HTTP connection (1): de.yunpoc.edu.tw:3000
2024-08-13 20:38:58 - urllib3.connectionpool - DEBUG - http://de.yunpoc.edu.tw:3000 "POST /fido2/login/begin HTTP/1.1" 200 648
2024-08-13 20:39:05 - urllib3.connectionpool - DEBUG - Starting new HTTP connection (1): de.yunpoc.edu.tw:3000
2024-08-13 20:39:05 - urllib3.connectionpool - DEBUG - http://de.yunpoc.edu.tw:3000 "POST /fido2/login/complete HTTP/1.1" 500 64
2024-08-13 20:39:05 - grpc._server - ERROR - Exception calling application: 'data'
Traceback (most recent call last):
  File "/home/yunpep/non_web_protocal_zta/PEP/server/index/myvenv/lib/python3.12/site-packages/grpc/_server.py", line 609, in _call_behavior
    response_or_iterator = behavior(argument, context)
                           ^^^^^^^^^^^^^^^^^^^^^^^^^^^
  File "/home/yunpep/non_web_protocal_zta/PEP/server/index/grpc_server.py", line 146, in LoginComplete
    return credentials_pb2.Message(msg=message['data'])
                                       ~~~~~~~^^^^^^^^
KeyError: 'data'
2024-08-13 20:39:23 - urllib3.connectionpool - DEBUG - Starting new HTTP connection (1): de.yunpoc.edu.tw:3000
2024-08-13 20:39:23 - urllib3.connectionpool - DEBUG - http://de.yunpoc.edu.tw:3000 "POST /fido2/login/begin HTTP/1.1" 200 648
2024-08-13 20:39:31 - urllib3.connectionpool - DEBUG - Starting new HTTP connection (1): de.yunpoc.edu.tw:3000
2024-08-13 20:39:31 - urllib3.connectionpool - DEBUG - http://de.yunpoc.edu.tw:3000 "POST /fido2/login/complete HTTP/1.1" 500 64
2024-08-13 20:39:31 - grpc._server - ERROR - Exception calling application: 'data'
Traceback (most recent call last):
  File "/home/yunpep/non_web_protocal_zta/PEP/server/index/myvenv/lib/python3.12/site-packages/grpc/_server.py", line 609, in _call_behavior
    response_or_iterator = behavior(argument, context)
                           ^^^^^^^^^^^^^^^^^^^^^^^^^^^
  File "/home/yunpep/non_web_protocal_zta/PEP/server/index/grpc_server.py", line 146, in LoginComplete
    return credentials_pb2.Message(msg=message['data'])
                                       ~~~~~~~^^^^^^^^
KeyError: 'data'
2024-08-13 20:40:11 - urllib3.connectionpool - DEBUG - Starting new HTTP connection (1): de.yunpoc.edu.tw:3000
2024-08-13 20:40:11 - urllib3.connectionpool - DEBUG - http://de.yunpoc.edu.tw:3000 "POST /fido2/login/begin HTTP/1.1" 200 648
2024-08-13 20:40:19 - urllib3.connectionpool - DEBUG - Starting new HTTP connection (1): de.yunpoc.edu.tw:3000
2024-08-13 20:40:19 - urllib3.connectionpool - DEBUG - http://de.yunpoc.edu.tw:3000 "POST /fido2/login/complete HTTP/1.1" 500 64
2024-08-13 20:40:19 - grpc._server - ERROR - Exception calling application: 'data'
Traceback (most recent call last):
  File "/home/yunpep/non_web_protocal_zta/PEP/server/index/myvenv/lib/python3.12/site-packages/grpc/_server.py", line 609, in _call_behavior
    response_or_iterator = behavior(argument, context)
                           ^^^^^^^^^^^^^^^^^^^^^^^^^^^
  File "/home/yunpep/non_web_protocal_zta/PEP/server/index/grpc_server.py", line 146, in LoginComplete
    return credentials_pb2.Message(msg=message['data'])
                                       ~~~~~~~^^^^^^^^
KeyError: 'data'
2024-08-13 20:42:38 - urllib3.connectionpool - DEBUG - Starting new HTTP connection (1): de.yunpoc.edu.tw:3000
2024-08-13 20:42:38 - urllib3.connectionpool - DEBUG - http://de.yunpoc.edu.tw:3000 "POST /fido2/register/begin HTTP/1.1" 200 1477
2024-08-13 20:42:48 - urllib3.connectionpool - DEBUG - Starting new HTTP connection (1): de.yunpoc.edu.tw:3000
2024-08-13 20:42:48 - urllib3.connectionpool - DEBUG - http://de.yunpoc.edu.tw:3000 "POST /fido2/register/complete HTTP/1.1" 200 48
2024-08-13 20:43:35 - urllib3.connectionpool - DEBUG - Starting new HTTP connection (1): de.yunpoc.edu.tw:3000
2024-08-13 20:43:35 - urllib3.connectionpool - DEBUG - http://de.yunpoc.edu.tw:3000 "POST /fido2/login/begin HTTP/1.1" 500 64
2024-08-13 20:43:35 - grpc._common - ERROR - Exception serializing message!
Traceback (most recent call last):
  File "/home/yunpep/non_web_protocal_zta/PEP/server/index/myvenv/lib/python3.12/site-packages/grpc/_common.py", line 89, in _transform
    return transformer(message)
           ^^^^^^^^^^^^^^^^^^^^
TypeError: descriptor 'SerializeToString' for 'google._upb._message.Message' objects doesn't apply to a 'NoneType' object
2024-08-13 20:43:47 - urllib3.connectionpool - DEBUG - Starting new HTTP connection (1): de.yunpoc.edu.tw:3000
2024-08-13 20:43:47 - urllib3.connectionpool - DEBUG - http://de.yunpoc.edu.tw:3000 "POST /fido2/login/begin HTTP/1.1" 500 64
2024-08-13 20:43:47 - grpc._common - ERROR - Exception serializing message!
Traceback (most recent call last):
  File "/home/yunpep/non_web_protocal_zta/PEP/server/index/myvenv/lib/python3.12/site-packages/grpc/_common.py", line 89, in _transform
    return transformer(message)
           ^^^^^^^^^^^^^^^^^^^^
TypeError: descriptor 'SerializeToString' for 'google._upb._message.Message' objects doesn't apply to a 'NoneType' object
2024-08-13 20:43:53 - urllib3.connectionpool - DEBUG - Starting new HTTP connection (1): de.yunpoc.edu.tw:3000
2024-08-13 20:43:53 - urllib3.connectionpool - DEBUG - http://de.yunpoc.edu.tw:3000 "POST /fido2/login/begin HTTP/1.1" 500 64
2024-08-13 20:43:53 - grpc._common - ERROR - Exception serializing message!
Traceback (most recent call last):
  File "/home/yunpep/non_web_protocal_zta/PEP/server/index/myvenv/lib/python3.12/site-packages/grpc/_common.py", line 89, in _transform
    return transformer(message)
           ^^^^^^^^^^^^^^^^^^^^
TypeError: descriptor 'SerializeToString' for 'google._upb._message.Message' objects doesn't apply to a 'NoneType' object
2024-08-13 20:43:59 - urllib3.connectionpool - DEBUG - Starting new HTTP connection (1): de.yunpoc.edu.tw:3000
2024-08-13 20:43:59 - urllib3.connectionpool - DEBUG - http://de.yunpoc.edu.tw:3000 "POST /fido2/login/begin HTTP/1.1" 500 64
2024-08-13 20:43:59 - grpc._common - ERROR - Exception serializing message!
Traceback (most recent call last):
  File "/home/yunpep/non_web_protocal_zta/PEP/server/index/myvenv/lib/python3.12/site-packages/grpc/_common.py", line 89, in _transform
    return transformer(message)
           ^^^^^^^^^^^^^^^^^^^^
TypeError: descriptor 'SerializeToString' for 'google._upb._message.Message' objects doesn't apply to a 'NoneType' object
2024-08-13 20:47:39 - urllib3.connectionpool - DEBUG - Starting new HTTP connection (1): de.yunpoc.edu.tw:3000
2024-08-13 20:47:40 - urllib3.connectionpool - DEBUG - http://de.yunpoc.edu.tw:3000 "POST /fido2/register/begin HTTP/1.1" 200 1477
2024-08-13 20:47:48 - urllib3.connectionpool - DEBUG - Starting new HTTP connection (1): de.yunpoc.edu.tw:3000
2024-08-13 20:47:49 - urllib3.connectionpool - DEBUG - http://de.yunpoc.edu.tw:3000 "POST /fido2/register/complete HTTP/1.1" 200 48
2024-08-13 20:50:06 - urllib3.connectionpool - DEBUG - Starting new HTTP connection (1): de.yunpoc.edu.tw:3000
2024-08-13 20:50:06 - urllib3.connectionpool - DEBUG - http://de.yunpoc.edu.tw:3000 "POST /fido2/register/begin HTTP/1.1" 200 1477
2024-08-13 20:50:15 - urllib3.connectionpool - DEBUG - Starting new HTTP connection (1): de.yunpoc.edu.tw:3000
2024-08-13 20:50:15 - urllib3.connectionpool - DEBUG - http://de.yunpoc.edu.tw:3000 "POST /fido2/register/complete HTTP/1.1" 200 48
2024-08-13 20:51:07 - urllib3.connectionpool - DEBUG - Starting new HTTP connection (1): de.yunpoc.edu.tw:3000
2024-08-13 20:51:07 - urllib3.connectionpool - DEBUG - http://de.yunpoc.edu.tw:3000 "POST /fido2/login/begin HTTP/1.1" 500 64
2024-08-13 20:51:07 - grpc._common - ERROR - Exception serializing message!
Traceback (most recent call last):
  File "/home/yunpep/non_web_protocal_zta/PEP/server/index/myvenv/lib/python3.12/site-packages/grpc/_common.py", line 89, in _transform
    return transformer(message)
           ^^^^^^^^^^^^^^^^^^^^
TypeError: descriptor 'SerializeToString' for 'google._upb._message.Message' objects doesn't apply to a 'NoneType' object
2024-08-13 20:52:05 - urllib3.connectionpool - DEBUG - Starting new HTTP connection (1): de.yunpoc.edu.tw:3000
2024-08-13 20:52:05 - urllib3.connectionpool - DEBUG - http://de.yunpoc.edu.tw:3000 "POST /fido2/login/begin HTTP/1.1" 200 589
2024-08-13 20:52:13 - urllib3.connectionpool - DEBUG - Starting new HTTP connection (1): de.yunpoc.edu.tw:3000
2024-08-13 20:52:13 - urllib3.connectionpool - DEBUG - http://de.yunpoc.edu.tw:3000 "POST /fido2/login/complete HTTP/1.1" 500 64
2024-08-13 20:52:13 - grpc._server - ERROR - Exception calling application: 'data'
Traceback (most recent call last):
  File "/home/yunpep/non_web_protocal_zta/PEP/server/index/myvenv/lib/python3.12/site-packages/grpc/_server.py", line 609, in _call_behavior
    response_or_iterator = behavior(argument, context)
                           ^^^^^^^^^^^^^^^^^^^^^^^^^^^
  File "/home/yunpep/non_web_protocal_zta/PEP/server/index/grpc_server.py", line 146, in LoginComplete
    return credentials_pb2.Message(msg=message['data'])
                                       ~~~~~~~^^^^^^^^
KeyError: 'data'
2024-08-13 20:52:39 - urllib3.connectionpool - DEBUG - Starting new HTTP connection (1): de.yunpoc.edu.tw:3000
2024-08-13 20:52:39 - urllib3.connectionpool - DEBUG - http://de.yunpoc.edu.tw:3000 "POST /fido2/login/begin HTTP/1.1" 200 589
2024-08-13 20:52:46 - urllib3.connectionpool - DEBUG - Starting new HTTP connection (1): de.yunpoc.edu.tw:3000
2024-08-13 20:52:46 - urllib3.connectionpool - DEBUG - http://de.yunpoc.edu.tw:3000 "POST /fido2/login/complete HTTP/1.1" 500 64
2024-08-13 20:52:46 - grpc._server - ERROR - Exception calling application: 'data'
Traceback (most recent call last):
  File "/home/yunpep/non_web_protocal_zta/PEP/server/index/myvenv/lib/python3.12/site-packages/grpc/_server.py", line 609, in _call_behavior
    response_or_iterator = behavior(argument, context)
                           ^^^^^^^^^^^^^^^^^^^^^^^^^^^
  File "/home/yunpep/non_web_protocal_zta/PEP/server/index/grpc_server.py", line 146, in LoginComplete
    return credentials_pb2.Message(msg=message['data'])
                                       ~~~~~~~^^^^^^^^
KeyError: 'data'
2024-08-13 20:54:37 - urllib3.connectionpool - DEBUG - Starting new HTTP connection (1): de.yunpoc.edu.tw:3000
2024-08-13 20:54:37 - urllib3.connectionpool - DEBUG - http://de.yunpoc.edu.tw:3000 "POST /fido2/login/begin HTTP/1.1" 200 589
2024-08-13 20:54:54 - urllib3.connectionpool - DEBUG - Starting new HTTP connection (1): de.yunpoc.edu.tw:3000
2024-08-13 20:54:54 - urllib3.connectionpool - DEBUG - http://de.yunpoc.edu.tw:3000 "POST /fido2/login/complete HTTP/1.1" 500 64
2024-08-13 20:54:54 - grpc._server - ERROR - Exception calling application: 'data'
Traceback (most recent call last):
  File "/home/yunpep/non_web_protocal_zta/PEP/server/index/myvenv/lib/python3.12/site-packages/grpc/_server.py", line 609, in _call_behavior
    response_or_iterator = behavior(argument, context)
                           ^^^^^^^^^^^^^^^^^^^^^^^^^^^
  File "/home/yunpep/non_web_protocal_zta/PEP/server/index/grpc_server.py", line 146, in LoginComplete
    return credentials_pb2.Message(msg=message['data'])
                                       ~~~~~~~^^^^^^^^
KeyError: 'data'
2024-08-13 20:55:47 - urllib3.connectionpool - DEBUG - Starting new HTTP connection (1): de.yunpoc.edu.tw:3000
2024-08-13 20:55:47 - urllib3.connectionpool - DEBUG - http://de.yunpoc.edu.tw:3000 "POST /fido2/login/begin HTTP/1.1" 200 589
2024-08-13 20:55:56 - urllib3.connectionpool - DEBUG - Starting new HTTP connection (1): de.yunpoc.edu.tw:3000
2024-08-13 20:55:56 - urllib3.connectionpool - DEBUG - http://de.yunpoc.edu.tw:3000 "POST /fido2/login/complete HTTP/1.1" 500 64
2024-08-13 20:55:56 - grpc._server - ERROR - Exception calling application: 'data'
Traceback (most recent call last):
  File "/home/yunpep/non_web_protocal_zta/PEP/server/index/myvenv/lib/python3.12/site-packages/grpc/_server.py", line 609, in _call_behavior
    response_or_iterator = behavior(argument, context)
                           ^^^^^^^^^^^^^^^^^^^^^^^^^^^
  File "/home/yunpep/non_web_protocal_zta/PEP/server/index/grpc_server.py", line 146, in LoginComplete
    return credentials_pb2.Message(msg=message['data'])
                                       ~~~~~~~^^^^^^^^
KeyError: 'data'
2024-08-13 20:56:15 - urllib3.connectionpool - DEBUG - Starting new HTTP connection (1): de.yunpoc.edu.tw:3000
2024-08-13 20:56:15 - urllib3.connectionpool - DEBUG - http://de.yunpoc.edu.tw:3000 "POST /fido2/login/begin HTTP/1.1" 200 589
2024-08-13 20:56:22 - urllib3.connectionpool - DEBUG - Starting new HTTP connection (1): de.yunpoc.edu.tw:3000
2024-08-13 20:56:23 - urllib3.connectionpool - DEBUG - http://de.yunpoc.edu.tw:3000 "POST /fido2/login/complete HTTP/1.1" 500 64
2024-08-13 20:56:23 - grpc._server - ERROR - Exception calling application: 'data'
Traceback (most recent call last):
  File "/home/yunpep/non_web_protocal_zta/PEP/server/index/myvenv/lib/python3.12/site-packages/grpc/_server.py", line 609, in _call_behavior
    response_or_iterator = behavior(argument, context)
                           ^^^^^^^^^^^^^^^^^^^^^^^^^^^
  File "/home/yunpep/non_web_protocal_zta/PEP/server/index/grpc_server.py", line 146, in LoginComplete
    return credentials_pb2.Message(msg=message['data'])
                                       ~~~~~~~^^^^^^^^
KeyError: 'data'
2024-08-13 21:00:23 - urllib3.connectionpool - DEBUG - Starting new HTTP connection (1): de.yunpoc.edu.tw:3000
2024-08-13 21:00:23 - urllib3.connectionpool - DEBUG - http://de.yunpoc.edu.tw:3000 "POST /fido2/register/begin HTTP/1.1" 200 1477
2024-08-13 21:00:33 - urllib3.connectionpool - DEBUG - Starting new HTTP connection (1): de.yunpoc.edu.tw:3000
2024-08-13 21:00:33 - urllib3.connectionpool - DEBUG - http://de.yunpoc.edu.tw:3000 "POST /fido2/register/complete HTTP/1.1" 200 48
2024-08-13 21:01:55 - urllib3.connectionpool - DEBUG - Starting new HTTP connection (1): de.yunpoc.edu.tw:3000
2024-08-13 21:01:55 - urllib3.connectionpool - DEBUG - http://de.yunpoc.edu.tw:3000 "POST /fido2/register/begin HTTP/1.1" 200 1477
2024-08-13 21:02:04 - urllib3.connectionpool - DEBUG - Starting new HTTP connection (1): de.yunpoc.edu.tw:3000
2024-08-13 21:02:04 - urllib3.connectionpool - DEBUG - http://de.yunpoc.edu.tw:3000 "POST /fido2/register/complete HTTP/1.1" 500 64
2024-08-13 21:02:04 - grpc._server - ERROR - Exception calling application: 'data'
Traceback (most recent call last):
  File "/home/yunpep/non_web_protocal_zta/PEP/server/index/myvenv/lib/python3.12/site-packages/grpc/_server.py", line 609, in _call_behavior
    response_or_iterator = behavior(argument, context)
                           ^^^^^^^^^^^^^^^^^^^^^^^^^^^
  File "/home/yunpep/non_web_protocal_zta/PEP/server/index/grpc_server.py", line 177, in RegisterComplete
    return credentials_pb2.Message(msg=message['data'])
                                       ~~~~~~~^^^^^^^^
KeyError: 'data'
2024-08-13 21:02:29 - urllib3.connectionpool - DEBUG - Starting new HTTP connection (1): de.yunpoc.edu.tw:3000
2024-08-13 21:02:29 - urllib3.connectionpool - DEBUG - http://de.yunpoc.edu.tw:3000 "POST /fido2/register/begin HTTP/1.1" 200 1477
2024-08-13 21:02:38 - urllib3.connectionpool - DEBUG - Starting new HTTP connection (1): de.yunpoc.edu.tw:3000
2024-08-13 21:02:38 - urllib3.connectionpool - DEBUG - http://de.yunpoc.edu.tw:3000 "POST /fido2/register/complete HTTP/1.1" 200 48
2024-08-13 21:06:46 - urllib3.connectionpool - DEBUG - Starting new HTTP connection (1): de.yunpoc.edu.tw:3000
2024-08-13 21:06:46 - urllib3.connectionpool - DEBUG - http://de.yunpoc.edu.tw:3000 "POST /fido2/login/begin HTTP/1.1" 500 64
2024-08-13 21:06:46 - grpc._common - ERROR - Exception serializing message!
Traceback (most recent call last):
  File "/home/yunpep/non_web_protocal_zta/PEP/server/index/myvenv/lib/python3.12/site-packages/grpc/_common.py", line 89, in _transform
    return transformer(message)
           ^^^^^^^^^^^^^^^^^^^^
TypeError: descriptor 'SerializeToString' for 'google._upb._message.Message' objects doesn't apply to a 'NoneType' object
2024-08-13 21:07:04 - urllib3.connectionpool - DEBUG - Starting new HTTP connection (1): de.yunpoc.edu.tw:3000
2024-08-13 21:07:04 - urllib3.connectionpool - DEBUG - http://de.yunpoc.edu.tw:3000 "POST /fido2/login/begin HTTP/1.1" 200 525
2024-08-13 21:07:45 - urllib3.connectionpool - DEBUG - Starting new HTTP connection (1): de.yunpoc.edu.tw:3000
2024-08-13 21:07:45 - urllib3.connectionpool - DEBUG - http://de.yunpoc.edu.tw:3000 "POST /fido2/login/begin HTTP/1.1" 200 525
2024-08-13 21:08:25 - urllib3.connectionpool - DEBUG - Starting new HTTP connection (1): de.yunpoc.edu.tw:3000
2024-08-13 21:08:25 - urllib3.connectionpool - DEBUG - http://de.yunpoc.edu.tw:3000 "POST /fido2/login/begin HTTP/1.1" 200 525
2024-08-13 21:09:15 - urllib3.connectionpool - DEBUG - Starting new HTTP connection (1): de.yunpoc.edu.tw:3000
2024-08-13 21:09:15 - urllib3.connectionpool - DEBUG - http://de.yunpoc.edu.tw:3000 "POST /fido2/login/begin HTTP/1.1" 200 525
2024-08-13 21:09:50 - urllib3.connectionpool - DEBUG - Starting new HTTP connection (1): de.yunpoc.edu.tw:3000
2024-08-13 21:09:50 - urllib3.connectionpool - DEBUG - http://de.yunpoc.edu.tw:3000 "POST /fido2/login/begin HTTP/1.1" 200 589
2024-08-13 21:10:26 - urllib3.connectionpool - DEBUG - Starting new HTTP connection (1): de.yunpoc.edu.tw:3000
2024-08-13 21:10:26 - urllib3.connectionpool - DEBUG - http://de.yunpoc.edu.tw:3000 "POST /fido2/login/begin HTTP/1.1" 200 589
2024-08-13 21:10:33 - urllib3.connectionpool - DEBUG - Starting new HTTP connection (1): de.yunpoc.edu.tw:3000
2024-08-13 21:10:33 - urllib3.connectionpool - DEBUG - http://de.yunpoc.edu.tw:3000 "POST /fido2/login/complete HTTP/1.1" 500 64
2024-08-13 21:10:33 - grpc._server - ERROR - Exception calling application: 'data'
Traceback (most recent call last):
  File "/home/yunpep/non_web_protocal_zta/PEP/server/index/myvenv/lib/python3.12/site-packages/grpc/_server.py", line 609, in _call_behavior
    response_or_iterator = behavior(argument, context)
                           ^^^^^^^^^^^^^^^^^^^^^^^^^^^
  File "/home/yunpep/non_web_protocal_zta/PEP/server/index/grpc_server.py", line 146, in LoginComplete
    return credentials_pb2.Message(msg=message['data'])
                                       ~~~~~~~^^^^^^^^
KeyError: 'data'
2024-08-13 21:17:14 - urllib3.connectionpool - DEBUG - Starting new HTTP connection (1): de.yunpoc.edu.tw:3000
2024-08-13 21:17:14 - urllib3.connectionpool - DEBUG - http://de.yunpoc.edu.tw:3000 "POST /fido2/login/begin HTTP/1.1" 200 589
2024-08-13 21:17:21 - urllib3.connectionpool - DEBUG - Starting new HTTP connection (1): de.yunpoc.edu.tw:3000
2024-08-13 21:17:21 - urllib3.connectionpool - DEBUG - http://de.yunpoc.edu.tw:3000 "POST /fido2/login/complete HTTP/1.1" 500 64
2024-08-13 21:17:21 - grpc._server - ERROR - Exception calling application: 'data'
Traceback (most recent call last):
  File "/home/yunpep/non_web_protocal_zta/PEP/server/index/myvenv/lib/python3.12/site-packages/grpc/_server.py", line 609, in _call_behavior
    response_or_iterator = behavior(argument, context)
                           ^^^^^^^^^^^^^^^^^^^^^^^^^^^
  File "/home/yunpep/non_web_protocal_zta/PEP/server/index/grpc_server.py", line 146, in LoginComplete
    return credentials_pb2.Message(msg=message['data'])
                                       ~~~~~~~^^^^^^^^
KeyError: 'data'
2024-08-13 21:20:01 - urllib3.connectionpool - DEBUG - Starting new HTTP connection (1): de.yunpoc.edu.tw:3000
2024-08-13 21:20:01 - urllib3.connectionpool - DEBUG - http://de.yunpoc.edu.tw:3000 "POST /fido2/login/begin HTTP/1.1" 200 589
2024-08-13 21:20:09 - urllib3.connectionpool - DEBUG - Starting new HTTP connection (1): de.yunpoc.edu.tw:3000
2024-08-13 21:20:09 - urllib3.connectionpool - DEBUG - http://de.yunpoc.edu.tw:3000 "POST /fido2/login/complete HTTP/1.1" 500 64
2024-08-13 21:20:09 - grpc._server - ERROR - Exception calling application: 'data'
Traceback (most recent call last):
  File "/home/yunpep/non_web_protocal_zta/PEP/server/index/myvenv/lib/python3.12/site-packages/grpc/_server.py", line 609, in _call_behavior
    response_or_iterator = behavior(argument, context)
                           ^^^^^^^^^^^^^^^^^^^^^^^^^^^
  File "/home/yunpep/non_web_protocal_zta/PEP/server/index/grpc_server.py", line 146, in LoginComplete
    return credentials_pb2.Message(msg=message['data'])
                                       ~~~~~~~^^^^^^^^
KeyError: 'data'
2024-08-13 21:22:55 - urllib3.connectionpool - DEBUG - Starting new HTTP connection (1): de.yunpoc.edu.tw:3000
2024-08-13 21:22:55 - urllib3.connectionpool - DEBUG - http://de.yunpoc.edu.tw:3000 "POST /fido2/login/begin HTTP/1.1" 200 589
2024-08-13 21:23:03 - urllib3.connectionpool - DEBUG - Starting new HTTP connection (1): de.yunpoc.edu.tw:3000
2024-08-13 21:23:03 - urllib3.connectionpool - DEBUG - http://de.yunpoc.edu.tw:3000 "POST /fido2/login/complete HTTP/1.1" 500 64
2024-08-13 21:23:03 - grpc._server - ERROR - Exception calling application: 'data'
Traceback (most recent call last):
  File "/home/yunpep/non_web_protocal_zta/PEP/server/index/myvenv/lib/python3.12/site-packages/grpc/_server.py", line 609, in _call_behavior
    response_or_iterator = behavior(argument, context)
                           ^^^^^^^^^^^^^^^^^^^^^^^^^^^
  File "/home/yunpep/non_web_protocal_zta/PEP/server/index/grpc_server.py", line 146, in LoginComplete
    return credentials_pb2.Message(msg=message['data'])
                                       ~~~~~~~^^^^^^^^
KeyError: 'data'
2024-08-13 21:25:47 - urllib3.connectionpool - DEBUG - Starting new HTTP connection (1): de.yunpoc.edu.tw:3000
2024-08-13 21:25:47 - urllib3.connectionpool - DEBUG - http://de.yunpoc.edu.tw:3000 "POST /fido2/login/begin HTTP/1.1" 200 589
2024-08-13 21:25:54 - urllib3.connectionpool - DEBUG - Starting new HTTP connection (1): de.yunpoc.edu.tw:3000
2024-08-13 21:25:54 - urllib3.connectionpool - DEBUG - http://de.yunpoc.edu.tw:3000 "POST /fido2/login/complete HTTP/1.1" 500 64
2024-08-13 21:25:54 - grpc._server - ERROR - Exception calling application: 'data'
Traceback (most recent call last):
  File "/home/yunpep/non_web_protocal_zta/PEP/server/index/myvenv/lib/python3.12/site-packages/grpc/_server.py", line 609, in _call_behavior
    response_or_iterator = behavior(argument, context)
                           ^^^^^^^^^^^^^^^^^^^^^^^^^^^
  File "/home/yunpep/non_web_protocal_zta/PEP/server/index/grpc_server.py", line 146, in LoginComplete
    return credentials_pb2.Message(msg=message['data'])
                                       ~~~~~~~^^^^^^^^
KeyError: 'data'
2024-08-13 21:27:11 - urllib3.connectionpool - DEBUG - Starting new HTTP connection (1): de.yunpoc.edu.tw:3000
2024-08-13 21:27:11 - urllib3.connectionpool - DEBUG - http://de.yunpoc.edu.tw:3000 "POST /fido2/login/begin HTTP/1.1" 200 589
2024-08-13 21:27:19 - urllib3.connectionpool - DEBUG - Starting new HTTP connection (1): de.yunpoc.edu.tw:3000
2024-08-13 21:27:19 - urllib3.connectionpool - DEBUG - http://de.yunpoc.edu.tw:3000 "POST /fido2/login/complete HTTP/1.1" 200 43
2024-08-13 21:28:36 - urllib3.connectionpool - DEBUG - Starting new HTTP connection (1): de.yunpoc.edu.tw:3000
2024-08-13 21:28:36 - urllib3.connectionpool - DEBUG - http://de.yunpoc.edu.tw:3000 "POST /fido2/login/begin HTTP/1.1" 200 589
2024-08-13 21:28:44 - urllib3.connectionpool - DEBUG - Starting new HTTP connection (1): de.yunpoc.edu.tw:3000
2024-08-13 21:28:44 - urllib3.connectionpool - DEBUG - http://de.yunpoc.edu.tw:3000 "POST /fido2/login/complete HTTP/1.1" 200 43
2024-08-13 21:30:07 - urllib3.connectionpool - DEBUG - Starting new HTTP connection (1): de.yunpoc.edu.tw:3000
2024-08-13 21:30:07 - urllib3.connectionpool - DEBUG - http://de.yunpoc.edu.tw:3000 "POST /fido2/login/begin HTTP/1.1" 200 589
2024-08-13 21:30:16 - urllib3.connectionpool - DEBUG - Starting new HTTP connection (1): de.yunpoc.edu.tw:3000
2024-08-13 21:30:16 - urllib3.connectionpool - DEBUG - http://de.yunpoc.edu.tw:3000 "POST /fido2/login/complete HTTP/1.1" 200 45
